# 在案例中学习异常

1. 简单try……catch

   ```java
   public class ThrowableTest {
       public static void main(String[] args) {
           System.out.println("begin");
           try {
               int i = 1/0;
               System.out.println("try");
           } catch (Exception e) {
               System.out.println("catch");
   //            e.printStackTrace();
           }
           System.out.println("end");
       }
   }
   
   //执行结果
   /*
   	begin
   	catch
   	end
   */
   ```

   **学习知识点：**

   1. try和catch都不能单独使用，必须连用。
   2. 使用try-catch之后，程序遇到异常时不再中断执行，而是跳过异常代码及其之后的在try-catch中的剩余代码语句，来到catch代码块中执行我们定义的异常处理代码；

2. 使用try……catch捕获多个异常

   ```java
   public class ThrowableTest {
       public static void main(String[] args) {
           System.out.println("begin");
           try {
               int num = Integer.parseInt("xxxx");
   
               int i = 1/0;
               System.out.println("try");
           } catch (ArithmeticException e) {
               System.out.println("catch -- ArithmeticException");
           }catch (NumberFormatException e){
               System.out.println("catch -- NumberFormatException");
           }
           System.out.println("end");
       }
   }
   
   //执行结果
   /*
   	begin
   	catch -- NumberFormatException
   	end
   */
   ```

   **学习知识点：**

   1. 一个catch语句，只能捕获一种类型的异常，如果需要捕获多种异常类型，就得使用多个catch语句；
   2. try-catch中的代码在只会出现一种类型的异常，只能一个catch捕获，不可能同时匹配多个catch；
   3. 在有多个catch语句的代码中出现异常时，会从上到下依次匹配catch语句，所以多个catch语句应该按照从子类到父类的顺序依次定义；
   4. 一旦匹配上其中一个catch之后，便不会匹配剩余的catch，而是会跳出try-catch，执行之后的代码；

3. **来说说抛出异常吧**

   * **throw：**用于方法内部，用于给调用者返回一个异常对象，和return一样会结束当前方法；
     * throw new 异常类("异常信息");
   * **throws：**运用于方法声明之上，定义于方法参数之后，表示当前方法不处理异常，而是提醒该方法的调用者来处理抛出的异常(一个或者多个异常)；
     * private static int divide(int num1, int num2) throws Exception {}

4. **finally代码块**

   * finally语句块表示**无论如何**（也包括发生异常时）都会**最终执行**的代码块

   1. **try...finally：**

      ```java
      public class ThrowableTest {
          public static void main(String[] args) {
              System.out.println("begin");
              try {
                  int num = Integer.parseInt("xxxx");
      
                  int i = 1/0;
                  System.out.println("try");
              } finally {
                  System.out.println("finally");
              }
              System.out.println("end");
          }
      }
      
      //执行结果
      /*
      	begin
          Exception in thread "main" java.lang.NumberFormatException: For input string: "xxxx"
      	finally
      */
      ```

   2.  **try...catch....finally：**

      ```java
      public class ThrowableTest {
          public static void main(String[] args) {
              System.out.println("begin");
              try {
                  int num = Integer.parseInt("xxxx");
      
                  int i = 1/0;
                  System.out.println("try");
              } catch (ArithmeticException e) {
                  System.out.println("catch -- ArithmeticException");
      //            e.printStackTrace();
              }catch (NumberFormatException e){
                  System.out.println("catch -- NumberFormatException");
              }
              finally {
                  System.out.println("finally");
              }
              System.out.println("end");
          }
      }
      //执行结果
      /*
      	begin
      	catch -- NumberFormatException
      	finally
      	end
      */
      ```

      

   3. **finally不执行的情况：**当只有在try或者catch中**调用退出JVM的相关方法**，**此时finally才不会执行**，否则finally修饰的代码块永远会执行。比如：System.exit(0);//退出JVM

      ```java
      public class ThrowableTest {
          public static void main(String[] args) {
              System.out.println("begin");
              try {
                  int i = 1/0;
                  System.out.println("try");
              } catch (ArithmeticException e) {
                  System.out.println("catch -- ArithmeticException");
                  System.exit(0); //退出
              } finally {
                  System.out.println("finally");
              }
              System.out.println("end");
          }
      }
      //执行结果
      /*
      	begin
      	catch -- NumberFormatException
      */
      ```

      

   4. **finally 和 return**：如果finally中return语句同时存在，永远返回finally中的结果，但是应该避免这种情况的出现。

      ```java
      public class ThrowableTest {
          public static void main(String[] args) {
              System.out.println(test1());
          }
      
          public static int test1(){
              try{
                  return 12;
              }finally {
                  return 14;
              }
          }
      }
      //执行结果
      /*
      	14
      */
      ```

      *******

      ```java
      public class ThrowableTest {
          public static void main(String[] args) {
              System.out.println("main:a="+test1());
          }
      
          public static int test1(){
              int a = 13;
              try{
                  return a;
              }finally {
                  a++;
                  System.out.println("test:a="+a);
              }
          }
      }
      //执行结果
      /*
      	test:a=14
      	main:a=13
      */
      
      ```

      为什么会出现这种情况呢？首先finally肯定是会被执行的，所以a++之后a的值变成了14，但是finally中没有返回值，值为14的变量a并没有被返回；然后接着执行return a；这里的a的值在方法执行之初就已经确定了，故返回的值是13。

      